import ArticleLayout from "@/shared/components/article/ArticleLayout";

import photo1 from "./1.png";
import photo2 from "./2.png";
import photo3 from "./3.png";
import photo4 from "./4.png";
import photo5 from "./5.png";
import photo6 from "./6.png";
import photo7 from "./7.png";

export const article = {
  author: "Bee",
  date: "2025-02-10",
  title: "⚠️ Fetch & Axios Error Handling",
  description: "💡 Fetch와 Axios를 통한 에러 핸들링에 대한 정리글",
};

export const metadata = {
  title: article.title,
  description: article.description,
};

export default (props) => <ArticleLayout article={article} {...props} />;

<aside>💡 Fetch와 Axios를 통한 에러 핸들링에 대한 정리</aside>

## Error Layer

에러레이어를 구분 지었고, 큰 항목으로 구분지어 정리하였습니다.

1. Http - 4xx, Network
2. Application - throw Error
3. Suspense - UnhandledError(5xx, unknown)

## Axios (feat. [axios-mock-adapter](https://www.npmjs.com/package/axios-mock-adapter))

테스트에 앞서 기존 axiosClient/index.ts를 참조하지않고, 별도의 test.ts를 생성하여 baseUrl 설정을 localhost:3000으로 세팅한 이후 진행하였습니다.

## Network Error

<Image src={photo1} />

- 기존
  Network Error 에 대한 로깅이 `error(error.tsx)`, `warning(axios interceptor)` 에서 중복적으로 잡히고 있던 상황
- 변경
  Network Error 에 대한 로깅은 `warning(axios interceptor)` 에서만 로깅되도록 수정

  <Image src={photo2} />

      - 테스트 코드

          ```tsx
          const mock = new MockAdapter(axios)
                mock.onGet('/api/health').networkError()
                const test = axios.get('/api/health', {
                  method: 'GET'
                })
          ```

---

## 5xx Error

- 기존
  5xx에 대한 인스턴스를 생성하였으며, 조건문을 통해 500대 에러에 대한 별도의 에러 로깅이 이루어지고 있었던 상황 - 기존 코드

  ```tsx
  const handleServerInternalError = (
    response: AxiosResponse<ErrorResData>,
    error: AxiosError<ErrorResData>
  ) => {
    const message =
      response.status != serviceUnavailableStatusCode
        ? SERVER_ERROR_MSG
        : TEMP_SERVER_ERROR_MSG;
    const serviceInternalError = new ServerInternalError(
      message,
      error.response,
      error.request
    );
    window.Rollbar?.error(serviceInternalError, error, serviceInternalError);
    return Promise.reject(serviceInternalError);
  };
  if (error.response && server5xxStatusCode <= error.response.status) {
    return handleServerInternalError(response, error);
  }
  ```

- 변경
  5xx에 대한 에러는 error.tsx에서 UnKnownError 로 처리되게 로직 수정. 5xx대 에러에 대한 테스트를 진행

  <Image src={photo3} />

      - 테스트 코드

          ```tsx
          const mock = new MockAdapter(axios)
                mock.onGet('/api/health').reply(501)
                const test = axios.get('/api/health', {
                  method: 'GET'
                })
          ```

---

## 4xx Error

- 기존
  기존 ClientReqeustError 는 Error를 extends
- 변경
  AxiosError를 extends하는 구조로 변경
  <Image src={photo4} />

---

## Fetch

## NotFound

- 기존
  기존 notfound 페이지로 이동과 롤바 에러로깅이 되고 있는 상황
- 변경
  notfound 페이지 이동 시 notFoundError 시 페이지 리다이렉트만 되고 롤바 로깅은 되지 않도록 로직 수정 및 테스트
  [isNotFoundError()](https://github.com/vercel/next.js/blob/056b675bd94370e35ca91b8a08ad22bc63714c1b/packages/next/src/client/components/not-found.ts#L23) - 테스트 코드

  ```tsx
  catch (err: unknown) {
    if (isNotFoundError(err)) {
      return notFound()
    } else if (err instanceof ClientRequestError) {
      return notFound()
    } else {
      throw err
    }
  }
  ```

---

## 5xx

- 기존
  5xx 전체에 대한 에러를 ServerInternalError instance를 통해 에러로깅 - 기존코드

  ```jsx
  if (res.status >= 500) {
    rollbar.error(res)
    throw new ServerInternalError(JSON.parse(await res.text()).error.message)
  ```

- 변경
  500에러에 대한 에러와 header의 contentType이 json형식 조건문을 통해 ServerInternalError와 UnExpectedServerError 로 구분지어 에러로깅을 진행

UnExpectedServerError 의 경우에는 response의 status와 statusText를 로깅하는 구조
`ex)501,502,503…` - 500 && JSON 형식

<Image src={photo5} />

    - 이외( 501, 502, 503 &&  !JSON형식)

<Image src={photo6} />

    - 테스트코드

        ```jsx
        //server2.js
        //express 서버
        app.get('/test-error', (req, res) => {
          const errorCode = req.query.error

          switch (errorCode) {
            case '500':
              res.status(500).json({
                error: {
                  message: 'Internal Server Error'
                }
              })
              break
            case '501':
              res.status(501).send('Not Implemented')
              break
            case '502':
              res.status(502).send('Bad Gateway')
              break
            case '503':
              res.status(503).send('Service Unavailable')
              break
            case '504':
              res.status(504).send('Gateway Timeout')
              break
            default:
              res.send('No error code or unrecognized error code')
          }
        })

        const PORT = process.env.PORT || 8080
        app.listen(PORT, () => {
          console.log(`실행 중이다... ${PORT}`)
        })

        //fecthClient/test.ts
        const BASE_URL = 'http://localhost:8080' //baseUrl 수정

        //index.ts
        const testRes = await Fetch('/test-error?error=500', {
        	method: 'GET',
        	next: {
        		revalidate: 0
          }
        })
        ```

## 4xx

4xx대 에러에 대한 핸들링은 기존과 동일한 구조.

- 기존(현상 유지)
  <Image src={photo7} />
